{
    "url": "https://api.github.com/repos/rapidsai/cudf/issues/11791",
    "repository_url": "https://api.github.com/repos/rapidsai/cudf",
    "labels_url": "https://api.github.com/repos/rapidsai/cudf/issues/11791/labels{/name}",
    "comments_url": "https://api.github.com/repos/rapidsai/cudf/issues/11791/comments",
    "events_url": "https://api.github.com/repos/rapidsai/cudf/issues/11791/events",
    "html_url": "https://github.com/rapidsai/cudf/issues/11791",
    "id": 1388173691,
    "node_id": "I_kwDOBWUGps5Svdl7",
    "number": 11791,
    "title": "[BUG] Grouping by a nonexistent key gives `ValueError` rather than `KeyError`",
    "user": {
        "login": "shwina",
        "id": 3190405,
        "node_id": "MDQ6VXNlcjMxOTA0MDU=",
        "avatar_url": "https://avatars.githubusercontent.com/u/3190405?v=4",
        "gravatar_id": "",
        "url": "https://api.github.com/users/shwina",
        "html_url": "https://github.com/shwina",
        "followers_url": "https://api.github.com/users/shwina/followers",
        "following_url": "https://api.github.com/users/shwina/following{/other_user}",
        "gists_url": "https://api.github.com/users/shwina/gists{/gist_id}",
        "starred_url": "https://api.github.com/users/shwina/starred{/owner}{/repo}",
        "subscriptions_url": "https://api.github.com/users/shwina/subscriptions",
        "organizations_url": "https://api.github.com/users/shwina/orgs",
        "repos_url": "https://api.github.com/users/shwina/repos",
        "events_url": "https://api.github.com/users/shwina/events{/privacy}",
        "received_events_url": "https://api.github.com/users/shwina/received_events",
        "type": "User",
        "site_admin": false
    },
    "labels": [
        {
            "id": 599626559,
            "node_id": "MDU6TGFiZWw1OTk2MjY1NTk=",
            "url": "https://api.github.com/repos/rapidsai/cudf/labels/bug",
            "name": "bug",
            "color": "d73a4a",
            "default": true,
            "description": "Something isn't working"
        },
        {
            "id": 1139741213,
            "node_id": "MDU6TGFiZWwxMTM5NzQxMjEz",
            "url": "https://api.github.com/repos/rapidsai/cudf/labels/Python",
            "name": "Python",
            "color": "1d76db",
            "default": false,
            "description": "Affects Python cuDF API."
        }
    ],
    "state": "open",
    "locked": false,
    "assignee": null,
    "assignees": [],
    "milestone": null,
    "comments": 0,
    "created_at": "2022-09-27T18:15:34Z",
    "updated_at": "2022-09-27T18:15:44Z",
    "closed_at": null,
    "author_association": "CONTRIBUTOR",
    "active_lock_reason": null,
    "body": "I would expect the code below to raise a `KeyError`, but it raises a `ValueError` instead:\r\n\r\n```python\r\n>>> import cudf\r\n>>> df = cudf.DataFrame({'a': [1, 1, 2], 'b': [1, 2, 3]})\r\n>>> df.groupby('cd').sum() \r\n...\r\nValueError: Grouper and object must have same length\r\n```",
    "closed_by": null,
    "reactions": {
        "url": "https://api.github.com/repos/rapidsai/cudf/issues/11791/reactions",
        "total_count": 0,
        "+1": 0,
        "-1": 0,
        "laugh": 0,
        "hooray": 0,
        "confused": 0,
        "heart": 0,
        "rocket": 0,
        "eyes": 0
    },
    "timeline_url": "https://api.github.com/repos/rapidsai/cudf/issues/11791/timeline",
    "performed_via_github_app": null,
    "state_reason": null
}