{
    "url": "https://api.github.com/repos/rapidsai/cudf/issues/11434",
    "repository_url": "https://api.github.com/repos/rapidsai/cudf",
    "labels_url": "https://api.github.com/repos/rapidsai/cudf/issues/11434/labels{/name}",
    "comments_url": "https://api.github.com/repos/rapidsai/cudf/issues/11434/comments",
    "events_url": "https://api.github.com/repos/rapidsai/cudf/issues/11434/events",
    "html_url": "https://github.com/rapidsai/cudf/issues/11434",
    "id": 1326185130,
    "node_id": "I_kwDOBWUGps5PC_qq",
    "number": 11434,
    "title": "[BUG] Multiple DataFrame.loc operations gives confusing error message upon compute on Dask-cuDF",
    "user": {
        "login": "alextxu",
        "id": 38475194,
        "node_id": "MDQ6VXNlcjM4NDc1MTk0",
        "avatar_url": "https://avatars.githubusercontent.com/u/38475194?v=4",
        "gravatar_id": "",
        "url": "https://api.github.com/users/alextxu",
        "html_url": "https://github.com/alextxu",
        "followers_url": "https://api.github.com/users/alextxu/followers",
        "following_url": "https://api.github.com/users/alextxu/following{/other_user}",
        "gists_url": "https://api.github.com/users/alextxu/gists{/gist_id}",
        "starred_url": "https://api.github.com/users/alextxu/starred{/owner}{/repo}",
        "subscriptions_url": "https://api.github.com/users/alextxu/subscriptions",
        "organizations_url": "https://api.github.com/users/alextxu/orgs",
        "repos_url": "https://api.github.com/users/alextxu/repos",
        "events_url": "https://api.github.com/users/alextxu/events{/privacy}",
        "received_events_url": "https://api.github.com/users/alextxu/received_events",
        "type": "User",
        "site_admin": false
    },
    "labels": [
        {
            "id": 599626559,
            "node_id": "MDU6TGFiZWw1OTk2MjY1NTk=",
            "url": "https://api.github.com/repos/rapidsai/cudf/labels/bug",
            "name": "bug",
            "color": "d73a4a",
            "default": true,
            "description": "Something isn't working"
        },
        {
            "id": 1013987352,
            "node_id": "MDU6TGFiZWwxMDEzOTg3MzUy",
            "url": "https://api.github.com/repos/rapidsai/cudf/labels/0%20-%20Backlog",
            "name": "0 - Backlog",
            "color": "d4c5f9",
            "default": false,
            "description": "In queue waiting for assignment"
        },
        {
            "id": 1185240898,
            "node_id": "MDU6TGFiZWwxMTg1MjQwODk4",
            "url": "https://api.github.com/repos/rapidsai/cudf/labels/dask",
            "name": "dask",
            "color": "fcc25d",
            "default": false,
            "description": "Dask issue"
        }
    ],
    "state": "open",
    "locked": false,
    "assignee": null,
    "assignees": [],
    "milestone": null,
    "comments": 3,
    "created_at": "2022-08-02T17:46:45Z",
    "updated_at": "2022-10-21T07:14:05Z",
    "closed_at": null,
    "author_association": "NONE",
    "active_lock_reason": null,
    "body": "**Describe the bug**\r\nAfter creating a Dask-cuDF data frame, if I perform multiple .loc operations on it using boolean Dask-cuDF series, then when I compute the data frame, it produces a runtime error with the message `cuDF failure at: ../src/stream_compaction/apply_boolean_mask.cu:73: Column size mismatch`. A similar snippet works as expected on cuDF.\r\n\r\n**Steps/Code to reproduce bug**\r\n```python\r\nimport dask_cudf\r\nimport cudf\r\nddf1 = dask_cudf.from_cudf(cudf.DataFrame({'a':[1,2,3], 'b':[4,5,6]}), npartitions=2)\r\nf1 = dask_cudf.from_cudf(cudf.Series([False, True, True]), npartitions=2)\r\nf2 = dask_cudf.from_cudf(cudf.Series([True, False]), npartitions=2)\r\nddf2 = ddf1.loc[f1]\r\nddf3 = ddf2.loc[f2]\r\nprint(ddf2.compute())\r\nprint(ddf3.compute())\r\n```\r\nThe above code produces the following output:\r\n```\r\n   a  b                        \r\n1  2  5\r\n2  3  6                                                       \r\nTraceback (most recent call last):     \r\n  File \"temp.py\", line 9, in <module>\r\n    print(ddf3.compute())\r\n  File \"/opt/conda/lib/python3.8/site-packages/dask/base.py\", line 292, in compute\r\n    (result,) = compute(self, traverse=False, **kwargs)\r\n  File \"/opt/conda/lib/python3.8/site-packages/dask/base.py\", line 575, in compute\r\n    results = schedule(dsk, keys, **kwargs)    \r\n  File \"/opt/conda/lib/python3.8/site-packages/dask/local.py\", line 554, in get_sync\r\n    return get_async(                                         \r\n  File \"/opt/conda/lib/python3.8/site-packages/dask/local.py\", line 497, in get_async                                       \r\n    for key, res_info, failed in queue_get(queue).result():\r\n  File \"/opt/conda/lib/python3.8/concurrent/futures/_base.py\", line 437, in result\r\n    return self.__get_result()\r\n  File \"/opt/conda/lib/python3.8/concurrent/futures/_base.py\", line 389, in __get_result\r\n    raise self._exception\r\n  File \"/opt/conda/lib/python3.8/site-packages/dask/local.py\", line 539, in submit\r\n    fut.set_result(fn(*args, **kwargs))\r\n  File \"/opt/conda/lib/python3.8/site-packages/dask/local.py\", line 235, in batch_execute_tasks\r\n    return [execute_task(*a) for a in it]\r\n  File \"/opt/conda/lib/python3.8/site-packages/dask/local.py\", line 235, in <listcomp>\r\n    return [execute_task(*a) for a in it]\r\n  File \"/opt/conda/lib/python3.8/site-packages/dask/local.py\", line 226, in execute_task\r\n    result = pack_exception(e, dumps)\r\n  File \"/opt/conda/lib/python3.8/site-packages/dask/local.py\", line 221, in execute_task\r\n    result = _execute_task(task, data)\r\n  File \"/opt/conda/lib/python3.8/site-packages/dask/core.py\", line 119, in _execute_task\r\n    return func(*(_execute_task(a, cache) for a in args))\r\n  File \"/opt/conda/lib/python3.8/site-packages/dask/optimization.py\", line 990, in __call__\r\n    return core.get(self.dsk, self.outkey, dict(zip(self.inkeys, args)))\r\n  File \"/opt/conda/lib/python3.8/site-packages/dask/core.py\", line 149, in get\r\n    result = _execute_task(task, cache)\r\n  File \"/opt/conda/lib/python3.8/site-packages/dask/core.py\", line 119, in _execute_task\r\n    return func(*(_execute_task(a, cache) for a in args))\r\n  File \"/opt/conda/lib/python3.8/site-packages/dask/utils.py\", line 39, in apply\r\n    return func(*args, **kwargs)\r\n  File \"/opt/conda/lib/python3.8/site-packages/dask/dataframe/core.py\", line 6330, in apply_and_enforce\r\n    df = func(*args, **kwargs)\r\n  File \"/opt/conda/lib/python3.8/site-packages/dask/dataframe/methods.py\", line 37, in loc\r\n    return df.loc[iindexer]\r\n  File \"/opt/conda/lib/python3.8/site-packages/cudf/core/dataframe.py\", line 127, in __getitem__\r\n    return self._getitem_tuple_arg(arg)\r\n  File \"/opt/conda/lib/python3.8/site-packages/nvtx/nvtx.py\", line 101, in inner\r\n    result = func(*args, **kwargs)\r\n  File \"/opt/conda/lib/python3.8/site-packages/cudf/core/dataframe.py\", line 267, in _getitem_tuple_arg\r\n    df = columns_df._apply_boolean_mask(tmp_arg[0])\r\n  File \"/opt/conda/lib/python3.8/site-packages/cudf/core/indexed_frame.py\", line 1696, in _apply_boolean_mask\r\n    libcudf.stream_compaction.apply_boolean_mask(\r\n  File \"cudf/_lib/stream_compaction.pyx\", line 101, in cudf._lib.stream_compaction.apply_boolean_mask\r\nRuntimeError: cuDF failure at: ../src/stream_compaction/apply_boolean_mask.cu:73: Column size mismatch\r\n```\r\n\r\n**Expected behavior**\r\nExpected output (verified with cudf instead of dask-cudf):\r\n```\r\n   a  b\r\n1  2  5\r\n2  3  6\r\n   a  b\r\n1  2  5\r\n```\r\n\r\n**Environment overview (please complete the following information)**\r\n - Environment location: Docker\r\n - Method of cuDF install: Docker\r\n   - `docker run -it --rm --gpus all --ipc=host --network=host -v .`\r\n\r\n**Environment details**\r\ncuDF version 22.4.0a0+306.g0cb75a4913",
    "closed_by": null,
    "reactions": {
        "url": "https://api.github.com/repos/rapidsai/cudf/issues/11434/reactions",
        "total_count": 0,
        "+1": 0,
        "-1": 0,
        "laugh": 0,
        "hooray": 0,
        "confused": 0,
        "heart": 0,
        "rocket": 0,
        "eyes": 0
    },
    "timeline_url": "https://api.github.com/repos/rapidsai/cudf/issues/11434/timeline",
    "performed_via_github_app": null,
    "state_reason": null
}