{
    "url": "https://api.github.com/repos/rapidsai/cudf/issues/14505",
    "repository_url": "https://api.github.com/repos/rapidsai/cudf",
    "labels_url": "https://api.github.com/repos/rapidsai/cudf/issues/14505/labels{/name}",
    "comments_url": "https://api.github.com/repos/rapidsai/cudf/issues/14505/comments",
    "events_url": "https://api.github.com/repos/rapidsai/cudf/issues/14505/events",
    "html_url": "https://github.com/rapidsai/cudf/issues/14505",
    "id": 2012948196,
    "node_id": "I_kwDOBWUGps53-ybk",
    "number": 14505,
    "title": "[BUG] `np.<ufunc>()` returns `None` when passed a `cudf.MultiIndex`",
    "user": {
        "login": "vyasr",
        "id": 1538165,
        "node_id": "MDQ6VXNlcjE1MzgxNjU=",
        "avatar_url": "https://avatars.githubusercontent.com/u/1538165?v=4",
        "gravatar_id": "",
        "url": "https://api.github.com/users/vyasr",
        "html_url": "https://github.com/vyasr",
        "followers_url": "https://api.github.com/users/vyasr/followers",
        "following_url": "https://api.github.com/users/vyasr/following{/other_user}",
        "gists_url": "https://api.github.com/users/vyasr/gists{/gist_id}",
        "starred_url": "https://api.github.com/users/vyasr/starred{/owner}{/repo}",
        "subscriptions_url": "https://api.github.com/users/vyasr/subscriptions",
        "organizations_url": "https://api.github.com/users/vyasr/orgs",
        "repos_url": "https://api.github.com/users/vyasr/repos",
        "events_url": "https://api.github.com/users/vyasr/events{/privacy}",
        "received_events_url": "https://api.github.com/users/vyasr/received_events",
        "type": "User",
        "site_admin": false
    },
    "labels": [
        {
            "id": 599626559,
            "node_id": "MDU6TGFiZWw1OTk2MjY1NTk=",
            "url": "https://api.github.com/repos/rapidsai/cudf/labels/bug",
            "name": "bug",
            "color": "d73a4a",
            "default": true,
            "description": "Something isn't working"
        },
        {
            "id": 1013987352,
            "node_id": "MDU6TGFiZWwxMDEzOTg3MzUy",
            "url": "https://api.github.com/repos/rapidsai/cudf/labels/0%20-%20Backlog",
            "name": "0 - Backlog",
            "color": "d4c5f9",
            "default": false,
            "description": "In queue waiting for assignment"
        },
        {
            "id": 1139741213,
            "node_id": "MDU6TGFiZWwxMTM5NzQxMjEz",
            "url": "https://api.github.com/repos/rapidsai/cudf/labels/Python",
            "name": "Python",
            "color": "1d76db",
            "default": false,
            "description": "Affects Python cuDF API."
        }
    ],
    "state": "open",
    "locked": false,
    "assignee": null,
    "assignees": [],
    "milestone": null,
    "comments": 0,
    "created_at": "2023-11-27T19:26:59Z",
    "updated_at": "2023-12-14T19:09:31Z",
    "closed_at": null,
    "author_association": "CONTRIBUTOR",
    "active_lock_reason": null,
    "body": "**Describe the bug**\r\n`np.exp` silently returns `None` for `cudf.MultiIndex`\r\n\r\n**Steps/Code to reproduce bug**\r\n```\r\nIn [1]: import numpy as np\r\nIn [2]: import cudf\r\nIn [3]: np.exp(cudf.MultiIndex.from_tuples([(1, 2), (3, 4)]))  # returns None\r\n```\r\n\r\n**Expected behavior**\r\nThis code should raise an error, which is what happens with a `pandas.MultiIndex`\r\n```\r\nIn [4]: pandas as pd\r\nIn [5]: np.exp(pd.MultiIndex.from_tuples([(1, 2), (3, 4)]))\r\n...\r\nTypeError: loop of ufunc does not support argument 0 of type tuple which has no callable exp method\r\n```",
    "closed_by": null,
    "reactions": {
        "url": "https://api.github.com/repos/rapidsai/cudf/issues/14505/reactions",
        "total_count": 0,
        "+1": 0,
        "-1": 0,
        "laugh": 0,
        "hooray": 0,
        "confused": 0,
        "heart": 0,
        "rocket": 0,
        "eyes": 0
    },
    "timeline_url": "https://api.github.com/repos/rapidsai/cudf/issues/14505/timeline",
    "performed_via_github_app": null,
    "state_reason": null
}