{
    "url": "https://api.github.com/repos/rapidsai/cudf/issues/13310",
    "repository_url": "https://api.github.com/repos/rapidsai/cudf",
    "labels_url": "https://api.github.com/repos/rapidsai/cudf/issues/13310/labels{/name}",
    "comments_url": "https://api.github.com/repos/rapidsai/cudf/issues/13310/comments",
    "events_url": "https://api.github.com/repos/rapidsai/cudf/issues/13310/events",
    "html_url": "https://github.com/rapidsai/cudf/issues/13310",
    "id": 1700828841,
    "node_id": "I_kwDOBWUGps5lYJap",
    "number": 13310,
    "title": "[BUG] Handle CudfException while instantiating ColumnViews ",
    "user": {
        "login": "razajafri",
        "id": 8813002,
        "node_id": "MDQ6VXNlcjg4MTMwMDI=",
        "avatar_url": "https://avatars.githubusercontent.com/u/8813002?v=4",
        "gravatar_id": "",
        "url": "https://api.github.com/users/razajafri",
        "html_url": "https://github.com/razajafri",
        "followers_url": "https://api.github.com/users/razajafri/followers",
        "following_url": "https://api.github.com/users/razajafri/following{/other_user}",
        "gists_url": "https://api.github.com/users/razajafri/gists{/gist_id}",
        "starred_url": "https://api.github.com/users/razajafri/starred{/owner}{/repo}",
        "subscriptions_url": "https://api.github.com/users/razajafri/subscriptions",
        "organizations_url": "https://api.github.com/users/razajafri/orgs",
        "repos_url": "https://api.github.com/users/razajafri/repos",
        "events_url": "https://api.github.com/users/razajafri/events{/privacy}",
        "received_events_url": "https://api.github.com/users/razajafri/received_events",
        "type": "User",
        "site_admin": false
    },
    "labels": [
        {
            "id": 599626559,
            "node_id": "MDU6TGFiZWw1OTk2MjY1NTk=",
            "url": "https://api.github.com/repos/rapidsai/cudf/labels/bug",
            "name": "bug",
            "color": "d73a4a",
            "default": true,
            "description": "Something isn't working"
        },
        {
            "id": 1013987352,
            "node_id": "MDU6TGFiZWwxMDEzOTg3MzUy",
            "url": "https://api.github.com/repos/rapidsai/cudf/labels/0%20-%20Backlog",
            "name": "0 - Backlog",
            "color": "d4c5f9",
            "default": false,
            "description": "In queue waiting for assignment"
        },
        {
            "id": 1405145623,
            "node_id": "MDU6TGFiZWwxNDA1MTQ1NjIz",
            "url": "https://api.github.com/repos/rapidsai/cudf/labels/Java",
            "name": "Java",
            "color": "006b75",
            "default": false,
            "description": "Affects Java cuDF API."
        },
        {
            "id": 1405146975,
            "node_id": "MDU6TGFiZWwxNDA1MTQ2OTc1",
            "url": "https://api.github.com/repos/rapidsai/cudf/labels/Spark",
            "name": "Spark",
            "color": "7400ff",
            "default": false,
            "description": "Functionality that helps Spark RAPIDS"
        }
    ],
    "state": "open",
    "locked": false,
    "assignee": null,
    "assignees": [],
    "milestone": null,
    "comments": 0,
    "created_at": "2023-05-08T19:47:50Z",
    "updated_at": "2023-06-07T21:05:59Z",
    "closed_at": null,
    "author_association": "CONTRIBUTOR",
    "active_lock_reason": null,
    "body": "**Describe the bug**\r\nWhile instantiating ColumnViews in a loop. We could run into a case where somewhere in the middle of the instantiations we see a `CudfException`. Any attempt to call `close()` on successfully instantiated `ColumnView`s might throw another `CudfException`, causing us to be irrecoverable. \r\n\r\n```\r\ntry {\r\n  columnViews[i] = new ColumnView();\r\n} catch (Throwable e) { \r\n  for (ColumnView cv: columnViews) {\r\n    if (cv != null) cv.close(); // this could again throw\r\n  }\r\n  throw t;\r\n}\r\n```\r\nRefer to https://github.com/rapidsai/cudf/pull/13262/files#diff-50ba2711690aca8e4f28d7b491373a4dd76443127c8b452a77b6c1fe2388d9e3R815-R828 for the exact example of this case. \r\n\r\n**Expected behavior**\r\nWe should be able to recover ideally although, not sure if we can. Is this an irrecoverable state and can we just let the exception propagate upstream? Could we add the original exception as a suppressed exception in the new exception? ",
    "closed_by": null,
    "reactions": {
        "url": "https://api.github.com/repos/rapidsai/cudf/issues/13310/reactions",
        "total_count": 0,
        "+1": 0,
        "-1": 0,
        "laugh": 0,
        "hooray": 0,
        "confused": 0,
        "heart": 0,
        "rocket": 0,
        "eyes": 0
    },
    "timeline_url": "https://api.github.com/repos/rapidsai/cudf/issues/13310/timeline",
    "performed_via_github_app": null,
    "state_reason": null
}