{
    "url": "https://api.github.com/repos/rapidsai/cudf/issues/11298",
    "repository_url": "https://api.github.com/repos/rapidsai/cudf",
    "labels_url": "https://api.github.com/repos/rapidsai/cudf/issues/11298/labels{/name}",
    "comments_url": "https://api.github.com/repos/rapidsai/cudf/issues/11298/comments",
    "events_url": "https://api.github.com/repos/rapidsai/cudf/issues/11298/events",
    "html_url": "https://github.com/rapidsai/cudf/issues/11298",
    "id": 1309800500,
    "node_id": "I_kwDOBWUGps5OEfg0",
    "number": 11298,
    "title": "[BUG] Assignment of string columns using `df.loc` fails with type error.",
    "user": {
        "login": "cwharris",
        "id": 1445368,
        "node_id": "MDQ6VXNlcjE0NDUzNjg=",
        "avatar_url": "https://avatars.githubusercontent.com/u/1445368?v=4",
        "gravatar_id": "",
        "url": "https://api.github.com/users/cwharris",
        "html_url": "https://github.com/cwharris",
        "followers_url": "https://api.github.com/users/cwharris/followers",
        "following_url": "https://api.github.com/users/cwharris/following{/other_user}",
        "gists_url": "https://api.github.com/users/cwharris/gists{/gist_id}",
        "starred_url": "https://api.github.com/users/cwharris/starred{/owner}{/repo}",
        "subscriptions_url": "https://api.github.com/users/cwharris/subscriptions",
        "organizations_url": "https://api.github.com/users/cwharris/orgs",
        "repos_url": "https://api.github.com/users/cwharris/repos",
        "events_url": "https://api.github.com/users/cwharris/events{/privacy}",
        "received_events_url": "https://api.github.com/users/cwharris/received_events",
        "type": "User",
        "site_admin": false
    },
    "labels": [
        {
            "id": 599626559,
            "node_id": "MDU6TGFiZWw1OTk2MjY1NTk=",
            "url": "https://api.github.com/repos/rapidsai/cudf/labels/bug",
            "name": "bug",
            "color": "d73a4a",
            "default": true,
            "description": "Something isn't working"
        },
        {
            "id": 1139741213,
            "node_id": "MDU6TGFiZWwxMTM5NzQxMjEz",
            "url": "https://api.github.com/repos/rapidsai/cudf/labels/Python",
            "name": "Python",
            "color": "1d76db",
            "default": false,
            "description": "Affects Python cuDF API."
        }
    ],
    "state": "open",
    "locked": false,
    "assignee": null,
    "assignees": [],
    "milestone": null,
    "comments": 1,
    "created_at": "2022-07-19T16:52:10Z",
    "updated_at": "2023-04-02T22:40:23Z",
    "closed_at": null,
    "author_association": "CONTRIBUTOR",
    "active_lock_reason": null,
    "body": "**Describe the bug**\r\nAssignment of string columns using `df.loc` fails with type error.\r\n\r\n**Steps/Code to reproduce bug**\r\n```python\r\nimport cudf\r\n\r\nvalues = list(['1', '2', '3', '4', '5', '6', '7', '8', '9', '0'])\r\n\r\ndf = cudf.DataFrame({\r\n    'existing_column': values[0:10]\r\n})\r\n\r\n# succeeds when creating new string column\r\ndf.loc[df.index[0:5], 'letters'] = values[0:5]\r\nprint(df)\r\n\r\n# fails with `ValueError: Unsupported dtype <U1` for existing string column\r\ndf.loc[df.index[5:10], 'letters'] = values[5:10]\r\nprint(df)\r\n```\r\n\r\n**Expected behavior**\r\nexpected string support when assigning slices of a DataFrame using `loc`.\r\n\r\n**Environment overview**\r\n - Environment location: Bare-metal\r\n - Method of cuDF install: conda\r\n\r\n**Additional context**\r\n```python\r\n$ python -c \\\r\n> \"\r\n> import cudf\r\n> \r\n> values = list(['1', '2', '3', '4', '5', '6', '7', '8', '9', '0'])\r\n> \r\n> df = cudf.DataFrame({\r\n>     'some_existing_column': values[0:10]\r\n> })\r\n> \r\n> df.loc[df.index[0:5], 'letters'] = values[0:5]\r\n> print(df)\r\n> \r\n> df.loc[df.index[5:10], 'letters'] = values[5:10]\r\n> print(df)\r\n> \"\r\n  some_existing_column letters\r\n0                    1       1\r\n1                    2       2\r\n2                    3       3\r\n3                    4       4\r\n4                    5       5\r\n5                    6    <NA>\r\n6                    7    <NA>\r\n7                    8    <NA>\r\n8                    9    <NA>\r\n9                    0    <NA>\r\nTraceback (most recent call last):\r\n  File \"<string>\", line 13, in <module>\r\n  File \"/home/charris/miniconda3/envs/morpheus/lib/python3.8/site-packages/cudf/core/dataframe.py\", line 143, in __setitem__\r\n    return self._setitem_tuple_arg(key, value)\r\n  File \"/home/charris/miniconda3/envs/morpheus/lib/python3.8/contextlib.py\", line 75, in inner\r\n    return func(*args, **kwds)\r\n  File \"/home/charris/miniconda3/envs/morpheus/lib/python3.8/site-packages/cudf/core/dataframe.py\", line 372, in _setitem_tuple_arg\r\n    value = cupy.asarray(value)\r\n  File \"/home/charris/miniconda3/envs/morpheus/lib/python3.8/site-packages/cupy/_creation/from_data.py\", line 66, in asarray\r\n    return _core.array(a, dtype, False, order)\r\n  File \"cupy/_core/core.pyx\", line 2164, in cupy._core.core.array\r\n  File \"cupy/_core/core.pyx\", line 2243, in cupy._core.core.array\r\n  File \"cupy/_core/core.pyx\", line 2315, in cupy._core.core._send_object_to_gpu\r\nValueError: Unsupported dtype <U1\r\n```\r\n",
    "closed_by": null,
    "reactions": {
        "url": "https://api.github.com/repos/rapidsai/cudf/issues/11298/reactions",
        "total_count": 0,
        "+1": 0,
        "-1": 0,
        "laugh": 0,
        "hooray": 0,
        "confused": 0,
        "heart": 0,
        "rocket": 0,
        "eyes": 0
    },
    "timeline_url": "https://api.github.com/repos/rapidsai/cudf/issues/11298/timeline",
    "performed_via_github_app": null,
    "state_reason": null
}